<?xml version="1.0" encoding="utf-8"?>
<!-- This URDF was automatically created by SolidWorks to URDF Exporter! Originally created by Stephen Brawner (brawner@gmail.com) 
     Commit Version: 1.6.0-4-g7f85cfe  Build Version: 1.6.7995.38578
     For more information, please see http://wiki.ros.org/sw_urdf_exporter -->
<robot
  name="sam_arm_right">
  <link
    name="base_link">
    <inertial>
      <origin
        xyz="-0.0885769875619264 -0.0110153111037166 0.0644546229363886"
        rpy="0 0 0" />
      <mass
        value="0.0665538972983176" />
      <inertia
        ixx="1.89633620910289E-05"
        ixy="-1.25424412154676E-06"
        ixz="-6.17451358505001E-07"
        iyy="1.54250481337256E-05"
        iyz="-1.70551961934911E-06"
        izz="2.59262342859442E-05" />
    </inertial>
    <visual>
      <origin
        xyz="0 0 0"
        rpy="0 0 0" />
      <geometry>
        <mesh
          filename="package://sam_arm_right/meshes/base_link.STL" />
      </geometry>
      <material
        name="">
        <color
          rgba="0.792156862745098 0.819607843137255 0.933333333333333 1" />
      </material>
    </visual>
    <collision>
      <origin
        xyz="0 0 0"
        rpy="0 0 0" />
      <geometry>
        <mesh
          filename="package://sam_arm_right/meshes/base_link.STL" />
      </geometry>
    </collision>
  </link>
  <link
    name="link_1">
    <inertial>
      <origin
        xyz="-0.00103585378114016 0.0293296868772498 0.0033875964244423"
        rpy="0 0 0" />
      <mass
        value="0.09587993219688" />
      <inertia
        ixx="3.29954205613336E-05"
        ixy="-2.87880408130399E-07"
        ixz="-3.48295403687381E-08"
        iyy="2.40473936181956E-05"
        iyz="-1.28348956500189E-06"
        izz="3.45004588971841E-05" />
    </inertial>
    <visual>
      <origin
        xyz="0 0 0"
        rpy="0 0 0" />
      <geometry>
        <mesh
          filename="package://sam_arm_right/meshes/link_1.STL" />
      </geometry>
      <material
        name="">
        <color
          rgba="0.792156862745098 0.819607843137255 0.933333333333333 1" />
      </material>
    </visual>
    <collision>
      <origin
        xyz="0 0 0"
        rpy="0 0 0" />
      <geometry>
        <mesh
          filename="package://sam_arm_right/meshes/link_1.STL" />
      </geometry>
    </collision>
  </link>
  <joint
    name="joint_1"
    type="revolute">
    <origin
      xyz="-0.086767563202787 -0.00405143203064752 0.085092758058752"
      rpy="1.5707963267949 -0.0147906192942683 -0.270070117807208" />
    <parent
      link="base_link" />
    <child
      link="link_1" />
    <axis
      xyz="0 -0.992759841107505 -0.120116184938593" />
    <limit
      lower="-3.14"
      upper="3.14"
      effort="5"
      velocity="1" />
  </joint>
  <link
    name="link_2">
    <inertial>
      <origin
        xyz="0.00968315406465067 0.0788604923694046 -0.0236733270280916"
        rpy="0 0 0" />
      <mass
        value="0.126266481388149" />
      <inertia
        ixx="6.18911360504117E-05"
        ixy="-5.32865572361757E-07"
        ixz="-3.04894000123864E-07"
        iyy="3.98975302772003E-05"
        iyz="-2.77363328847828E-07"
        izz="5.90849291620077E-05" />
    </inertial>
    <visual>
      <origin
        xyz="0 0 0"
        rpy="0 0 0" />
      <geometry>
        <mesh
          filename="package://sam_arm_right/meshes/link_2.STL" />
      </geometry>
      <material
        name="">
        <color
          rgba="0.792156862745098 0.819607843137255 0.933333333333333 1" />
      </material>
    </visual>
    <collision>
      <origin
        xyz="0 0 0"
        rpy="0 0 0" />
      <geometry>
        <mesh
          filename="package://sam_arm_right/meshes/link_2.STL" />
      </geometry>
    </collision>
  </link>
  <joint
    name="joint_2"
    type="revolute">
    <origin
      xyz="0.023600000000017 0.0520206156740432 0.00629408809077589"
      rpy="1.5707963267949 -0.120406913837309 1.5707963267949" />
    <parent
      link="link_1" />
    <child
      link="link_2" />
    <axis
      xyz="0 0 -1" />
    <limit
      lower="-3.14"
      upper="3.14"
      effort="5"
      velocity="1" />
  </joint>
  <link
    name="link_3">
    <inertial>
      <origin
        xyz="-0.00553674212877348 0.0852345126273742 -0.0298488070548564"
        rpy="0 0 0" />
      <mass
        value="0.126329667354128" />
      <inertia
        ixx="7.40696273279362E-05"
        ixy="2.8567877709257E-06"
        ixz="3.1405364773518E-08"
        iyy="2.82507182828393E-05"
        iyz="-5.10371627504126E-07"
        izz="5.96101977257255E-05" />
    </inertial>
    <visual>
      <origin
        xyz="0 0 0"
        rpy="0 0 0" />
      <geometry>
        <mesh
          filename="package://sam_arm_right/meshes/link_3.STL" />
      </geometry>
      <material
        name="">
        <color
          rgba="0.792156862745098 0.819607843137255 0.933333333333333 1" />
      </material>
    </visual>
    <collision>
      <origin
        xyz="0 0 0"
        rpy="0 0 0" />
      <geometry>
        <mesh
          filename="package://sam_arm_right/meshes/link_3.STL" />
      </geometry>
    </collision>
  </link>
  <joint
    name="joint_3"
    type="revolute">
    <origin
      xyz="0.031398 0.11261 0.0057"
      rpy="0 0 3.0999" />
    <parent
      link="link_2" />
    <child
      link="link_3" />
    <axis
      xyz="0 0 -1" />
    <limit
      lower="-3.14"
      upper="3.14"
      effort="5"
      velocity="1" />
  </joint>
  <link
    name="link_4">
    <inertial>
      <origin
        xyz="-0.00189064680232748 0.019219459458476 -0.0308395382423583"
        rpy="0 0 0" />
      <mass
        value="0.0363872452953952" />
      <inertia
        ixx="4.03714806542695E-06"
        ixy="-4.70491142214904E-08"
        ixz="5.61116135481473E-08"
        iyy="5.32741291463186E-06"
        iyz="4.305886701074E-09"
        izz="4.32710764578191E-06" />
    </inertial>
    <visual>
      <origin
        xyz="0 0 0"
        rpy="0 0 0" />
      <geometry>
        <mesh
          filename="package://sam_arm_right/meshes/link_4.STL" />
      </geometry>
      <material
        name="">
        <color
          rgba="0.792156862745098 0.819607843137255 0.933333333333333 1" />
      </material>
    </visual>
    <collision>
      <origin
        xyz="0 0 0"
        rpy="0 0 0" />
      <geometry>
        <mesh
          filename="package://sam_arm_right/meshes/link_4.STL" />
      </geometry>
    </collision>
  </link>
  <joint
    name="joint_4"
    type="revolute">
    <origin
      xyz="-0.0086135 0.13753 -0.0008"
      rpy="0 0 0" />
    <parent
      link="link_3" />
    <child
      link="link_4" />
    <axis
      xyz="0 0 -1" />
    <limit
      lower="-3.14"
      upper="3.14"
      effort="5"
      velocity="1" />
  </joint>
  <link
    name="link_5">
    <inertial>
      <origin
        xyz="0.0225081957654106 -5.84556943426795E-06 -0.0479431353278608"
        rpy="0 0 0" />
      <mass
        value="0.131547880525429" />
      <inertia
        ixx="3.00069610313384E-05"
        ixy="6.98749504391459E-11"
        ixz="-1.18872070947729E-06"
        iyy="4.48834102459926E-05"
        iyz="2.7899589724205E-10"
        izz="3.79171914009732E-05" />
    </inertial>
    <visual>
      <origin
        xyz="0 0 0"
        rpy="0 0 0" />
      <geometry>
        <mesh
          filename="package://sam_arm_right/meshes/link_5.STL" />
      </geometry>
      <material
        name="">
        <color
          rgba="1 1 1 1" />
      </material>
    </visual>
    <collision>
      <origin
        xyz="0 0 0"
        rpy="0 0 0" />
      <geometry>
        <mesh
          filename="package://sam_arm_right/meshes/link_5.STL" />
      </geometry>
    </collision>
  </link>
  <joint
    name="joint_5"
    type="revolute">
    <origin
      xyz="0.0259000000000474 0.0344999999998271 -0.0309000000000072"
      rpy="1.5707963267949 0.014477982951473 1.5707963267949" />
    <parent
      link="link_4" />
    <child
      link="link_5" />
    <axis
      xyz="0 0 -1" />
    <limit
      lower="-3.14"
      upper="3.14"
      effort="5"
      velocity="1" />
  </joint>
  <link
    name="link_6">
    <inertial>
      <origin
        xyz="-0.0038474 -0.0055891 -0.03227"
        rpy="0 0 0" />
      <mass
        value="0.10704" />
      <inertia
        ixx="7.7321E-05"
        ixy="-5.1449E-06"
        ixz="3.3748E-06"
        iyy="6.1034E-05"
        iyz="7.6486E-06"
        izz="5.467E-05" />
    </inertial>
    <visual>
      <origin
        xyz="0 0 0"
        rpy="0 0 0" />
      <geometry>
        <mesh
          filename="package://sam_arm_right/meshes/link_6.STL" />
      </geometry>
      <material
        name="">
        <color
          rgba="1 1 1 1" />
      </material>
    </visual>
    <collision>
      <origin
        xyz="0 0 0"
        rpy="0 0 0" />
      <geometry>
        <mesh
          filename="package://sam_arm_right/meshes/link_6.STL" />
      </geometry>
    </collision>
  </link>
  <joint
    name="joint_6"
    type="revolute">
    <origin
      xyz="0.0526 -0.0004 -0.019"
      rpy="1.5708 0 -1.8271" />
    <parent
      link="link_5" />
    <child
      link="link_6" />
    <axis
      xyz="0.25348 0 0.96734" />
    <limit
      lower="-3.14"
      upper="3.14"
      effort="5"
      velocity="1" />
  </joint>
  <link
    name="link_7">
    <inertial>
      <origin
        xyz="0.014936 0.029169 -0.019255"
        rpy="0 0 0" />
      <mass
        value="0.021865" />
      <inertia
        ixx="1.045E-05"
        ixy="-4.0768E-06"
        ixz="-9.6924E-08"
        iyy="5.3462E-06"
        iyz="-1.8696E-07"
        izz="1.0636E-05" />
    </inertial>
    <visual>
      <origin
        xyz="0 0 0"
        rpy="0 0 0" />
      <geometry>
        <mesh
          filename="package://sam_arm_right/meshes/link_7.STL" />
      </geometry>
      <material
        name="">
        <color
          rgba="0.79216 0.81961 0.93333 1" />
      </material>
    </visual>
    <collision>
      <origin
        xyz="0 0 0"
        rpy="0 0 0" />
      <geometry>
        <mesh
          filename="package://sam_arm_right/meshes/link_7.STL" />
      </geometry>
    </collision>
  </link>
  <joint
    name="joint_7"
    type="continuous">
    <origin
      xyz="-0.027157 0.017998 -0.022449"
      rpy="-1.5678 0.57594 0.011373" />
    <parent
      link="link_6" />
    <child
      link="link_7" />
    <axis
      xyz="0 0 -1" />
    <limit
      lower="-3.14"
      upper="3.14"
      effort="5"
      velocity="1" />
  </joint>
</robot>